Traceback (most recent call last):
  File "/Users/rodell/miniconda3/envs/opc/lib/python3.7/site-packages/jupyter_cache/executors/utils.py", line 56, in single_nb_execution
    record_timing=False,
  File "/Users/rodell/miniconda3/envs/opc/lib/python3.7/site-packages/nbclient/client.py", line 1082, in execute
    return NotebookClient(nb=nb, resources=resources, km=km, **kwargs).execute()
  File "/Users/rodell/miniconda3/envs/opc/lib/python3.7/site-packages/nbclient/util.py", line 74, in wrapped
    return just_run(coro(*args, **kwargs))
  File "/Users/rodell/miniconda3/envs/opc/lib/python3.7/site-packages/nbclient/util.py", line 53, in just_run
    return loop.run_until_complete(coro)
  File "/Users/rodell/miniconda3/envs/opc/lib/python3.7/asyncio/base_events.py", line 587, in run_until_complete
    return future.result()
  File "/Users/rodell/miniconda3/envs/opc/lib/python3.7/site-packages/nbclient/client.py", line 536, in async_execute
    cell, index, execution_count=self.code_cells_executed + 1
  File "/Users/rodell/miniconda3/envs/opc/lib/python3.7/site-packages/nbclient/client.py", line 827, in async_execute_cell
    self._check_raise_for_error(cell, exec_reply)
  File "/Users/rodell/miniconda3/envs/opc/lib/python3.7/site-packages/nbclient/client.py", line 735, in _check_raise_for_error
    raise CellExecutionError.from_cell_and_msg(cell, exec_reply['content'])
nbclient.exceptions.CellExecutionError: An error occurred while executing the following cell:
------------------
import context
import numpy as np
import pandas as pd
from functools import reduce
import matplotlib.pyplot as plt
from matplotlib.dates import DateFormatter
import matplotlib.pylab as pylab

from datetime import datetime, timedelta
from pathlib import Path
from context import data_dir, save_dir
------------------

[0;31m---------------------------------------------------------------------------[0m
[0;31mImportError[0m                               Traceback (most recent call last)
[0;32m<ipython-input-1-758c1babdea9>[0m in [0;36m<module>[0;34m[0m
[1;32m      9[0m [0;32mfrom[0m [0mdatetime[0m [0;32mimport[0m [0mdatetime[0m[0;34m,[0m [0mtimedelta[0m[0;34m[0m[0;34m[0m[0m
[1;32m     10[0m [0;32mfrom[0m [0mpathlib[0m [0;32mimport[0m [0mPath[0m[0;34m[0m[0;34m[0m[0m
[0;32m---> 11[0;31m [0;32mfrom[0m [0mcontext[0m [0;32mimport[0m [0mdata_dir[0m[0;34m,[0m [0msave_dir[0m[0;34m[0m[0;34m[0m[0m
[0m
[0;31mImportError[0m: cannot import name 'save_dir' from 'context' (/Users/rodell/a500_notebooks/context.py)
ImportError: cannot import name 'save_dir' from 'context' (/Users/rodell/a500_notebooks/context.py)

