Traceback (most recent call last):
  File "/Users/rodell/miniconda3/envs/opc/lib/python3.7/site-packages/jupyter_cache/executors/utils.py", line 56, in single_nb_execution
    record_timing=False,
  File "/Users/rodell/miniconda3/envs/opc/lib/python3.7/site-packages/nbclient/client.py", line 1082, in execute
    return NotebookClient(nb=nb, resources=resources, km=km, **kwargs).execute()
  File "/Users/rodell/miniconda3/envs/opc/lib/python3.7/site-packages/nbclient/util.py", line 74, in wrapped
    return just_run(coro(*args, **kwargs))
  File "/Users/rodell/miniconda3/envs/opc/lib/python3.7/site-packages/nbclient/util.py", line 53, in just_run
    return loop.run_until_complete(coro)
  File "/Users/rodell/miniconda3/envs/opc/lib/python3.7/asyncio/base_events.py", line 587, in run_until_complete
    return future.result()
  File "/Users/rodell/miniconda3/envs/opc/lib/python3.7/site-packages/nbclient/client.py", line 536, in async_execute
    cell, index, execution_count=self.code_cells_executed + 1
  File "/Users/rodell/miniconda3/envs/opc/lib/python3.7/site-packages/nbclient/client.py", line 827, in async_execute_cell
    self._check_raise_for_error(cell, exec_reply)
  File "/Users/rodell/miniconda3/envs/opc/lib/python3.7/site-packages/nbclient/client.py", line 735, in _check_raise_for_error
    raise CellExecutionError.from_cell_and_msg(cell, exec_reply['content'])
nbclient.exceptions.CellExecutionError: An error occurred while executing the following cell:
------------------
fig = plt.figure(figsize=(14, 6))
fig.suptitle("Counts/liter of particles of size XX um", fontsize=16)
ax = fig.add_subplot(1, 1, 1)
var_list = list(df_grim)[7:38]
# var_list = list(df_grim)[7:16]
for var in var_list:
  ax.plot(df_grim['date & time'],df_grim[var], lw = 2.0, label = var[:-2])
ax.set_ylabel('Counts/liter')
ax.set_xlabel('Time (MM-DD HH)')
ax.legend(
  bbox_to_anchor=(1.2, 1.2),
)
------------------

[0;31m---------------------------------------------------------------------------[0m
[0;31mKeyError[0m                                  Traceback (most recent call last)
[0;32m~/miniconda3/envs/opc/lib/python3.7/site-packages/pandas/core/indexes/base.py[0m in [0;36mget_loc[0;34m(self, key, method, tolerance)[0m
[1;32m   2890[0m             [0;32mtry[0m[0;34m:[0m[0;34m[0m[0;34m[0m[0m
[0;32m-> 2891[0;31m                 [0;32mreturn[0m [0mself[0m[0;34m.[0m[0m_engine[0m[0;34m.[0m[0mget_loc[0m[0;34m([0m[0mcasted_key[0m[0;34m)[0m[0;34m[0m[0;34m[0m[0m
[0m[1;32m   2892[0m             [0;32mexcept[0m [0mKeyError[0m [0;32mas[0m [0merr[0m[0;34m:[0m[0;34m[0m[0;34m[0m[0m

[0;32mpandas/_libs/index.pyx[0m in [0;36mpandas._libs.index.IndexEngine.get_loc[0;34m()[0m

[0;32mpandas/_libs/index.pyx[0m in [0;36mpandas._libs.index.IndexEngine.get_loc[0;34m()[0m

[0;32mpandas/_libs/hashtable_class_helper.pxi[0m in [0;36mpandas._libs.hashtable.PyObjectHashTable.get_item[0;34m()[0m

[0;32mpandas/_libs/hashtable_class_helper.pxi[0m in [0;36mpandas._libs.hashtable.PyObjectHashTable.get_item[0;34m()[0m

[0;31mKeyError[0m: 'date & time'

The above exception was the direct cause of the following exception:

[0;31mKeyError[0m                                  Traceback (most recent call last)
[0;32m<ipython-input-9-bff89e3418e6>[0m in [0;36m<module>[0;34m[0m
[1;32m      5[0m [0;31m# var_list = list(df_grim)[7:16][0m[0;34m[0m[0;34m[0m[0;34m[0m[0m
[1;32m      6[0m [0;32mfor[0m [0mvar[0m [0;32min[0m [0mvar_list[0m[0;34m:[0m[0;34m[0m[0;34m[0m[0m
[0;32m----> 7[0;31m   [0max[0m[0;34m.[0m[0mplot[0m[0;34m([0m[0mdf_grim[0m[0;34m[[0m[0;34m'date & time'[0m[0;34m][0m[0;34m,[0m[0mdf_grim[0m[0;34m[[0m[0mvar[0m[0;34m][0m[0;34m,[0m [0mlw[0m [0;34m=[0m [0;36m2.0[0m[0;34m,[0m [0mlabel[0m [0;34m=[0m [0mvar[0m[0;34m[[0m[0;34m:[0m[0;34m-[0m[0;36m2[0m[0;34m][0m[0;34m)[0m[0;34m[0m[0;34m[0m[0m
[0m[1;32m      8[0m [0max[0m[0;34m.[0m[0mset_ylabel[0m[0;34m([0m[0;34m'Counts/liter'[0m[0;34m)[0m[0;34m[0m[0;34m[0m[0m
[1;32m      9[0m [0max[0m[0;34m.[0m[0mset_xlabel[0m[0;34m([0m[0;34m'Time (MM-DD HH)'[0m[0;34m)[0m[0;34m[0m[0;34m[0m[0m

[0;32m~/miniconda3/envs/opc/lib/python3.7/site-packages/pandas/core/frame.py[0m in [0;36m__getitem__[0;34m(self, key)[0m
[1;32m   2900[0m             [0;32mif[0m [0mself[0m[0;34m.[0m[0mcolumns[0m[0;34m.[0m[0mnlevels[0m [0;34m>[0m [0;36m1[0m[0;34m:[0m[0;34m[0m[0;34m[0m[0m
[1;32m   2901[0m                 [0;32mreturn[0m [0mself[0m[0;34m.[0m[0m_getitem_multilevel[0m[0;34m([0m[0mkey[0m[0;34m)[0m[0;34m[0m[0;34m[0m[0m
[0;32m-> 2902[0;31m             [0mindexer[0m [0;34m=[0m [0mself[0m[0;34m.[0m[0mcolumns[0m[0;34m.[0m[0mget_loc[0m[0;34m([0m[0mkey[0m[0;34m)[0m[0;34m[0m[0;34m[0m[0m
[0m[1;32m   2903[0m             [0;32mif[0m [0mis_integer[0m[0;34m([0m[0mindexer[0m[0;34m)[0m[0;34m:[0m[0;34m[0m[0;34m[0m[0m
[1;32m   2904[0m                 [0mindexer[0m [0;34m=[0m [0;34m[[0m[0mindexer[0m[0;34m][0m[0;34m[0m[0;34m[0m[0m

[0;32m~/miniconda3/envs/opc/lib/python3.7/site-packages/pandas/core/indexes/base.py[0m in [0;36mget_loc[0;34m(self, key, method, tolerance)[0m
[1;32m   2891[0m                 [0;32mreturn[0m [0mself[0m[0;34m.[0m[0m_engine[0m[0;34m.[0m[0mget_loc[0m[0;34m([0m[0mcasted_key[0m[0;34m)[0m[0;34m[0m[0;34m[0m[0m
[1;32m   2892[0m             [0;32mexcept[0m [0mKeyError[0m [0;32mas[0m [0merr[0m[0;34m:[0m[0;34m[0m[0;34m[0m[0m
[0;32m-> 2893[0;31m                 [0;32mraise[0m [0mKeyError[0m[0;34m([0m[0mkey[0m[0;34m)[0m [0;32mfrom[0m [0merr[0m[0;34m[0m[0;34m[0m[0m
[0m[1;32m   2894[0m [0;34m[0m[0m
[1;32m   2895[0m         [0;32mif[0m [0mtolerance[0m [0;32mis[0m [0;32mnot[0m [0;32mNone[0m[0;34m:[0m[0;34m[0m[0;34m[0m[0m

[0;31mKeyError[0m: 'date & time'
KeyError: 'date & time'

